Workbook

Sheet Data
A1: s
B3: Data Collection Sheet
B4: Personal Details
B5: Particulars | C5: Self | E5: Spouse
B6: Name | C6: Partha Lalit | E6: NA
B7: Work Details | C7: Private Sector Job
B8: Designation | C8: Associate Engineer- Technology
B9: Company | C9: IRIS Software Technologies Pvt Ltd
B10: Work Experience (in years) | C10: 1.3
B11: Health History | C11: Fit
B12: Date of Birth (dd/mm/yyyy) | C12: 37599
B13: Current Age (Auto update) | C13: =TRUNC(YEARFRAC(C12,TODAY())) -> 23
B14: Mobile No. | C14: 7058132853
B15: Email ID | C15: 12parthlalit@gmail.com
B16: Communication Address | C16: 2/55, Bhagwati HSG SOC, Sai Nagar, Near RTO Office, Kuwarbav, Ratnagiri -415612
B17: Financial Freedom (targeted age) | C17: 50
B19: Family Details
B20: Particulars | C20: Child-1 | D20: Child-2 | E20: Father | F20: Mother | G20: Father in Law | H20: Mother in Law
B21: Name | F21: Anagha Lalit
B22: Current Status | F22: Financially Dependent
B23: Health History | F23: Fit
B24: Date of Birth (dd/mm/yyyy) | F24: 23597
B25: Current Age (Auto update) | C25: =TRUNC(YEARFRAC(C24,TODAY())) -> 126 | D25: =TRUNC(YEARFRAC(D24,TODAY())) -> 126 | F25: =TRUNC(YEARFRAC(F24,TODAY())) -> 61 | G25: =TRUNC(YEARFRAC(G24,TODAY())) -> 126 | H25: =TRUNC(YEARFRAC(H24,TODAY())) -> 126
B27: Major Goals
B28: Children's Future
B29: Child-1 Name | C29: =C21 -> 0
B30: Goal | C30: Graduation | D30: Post Graduation | E30: Marriage | F30: Others
B31: Goal Age
B32: Current Value
B33: Priority (H/M/L)
B35: Children's Future
B36: Child-2 Name | C36: =D21 -> 0
B37: Goal | C37: Graduation | D37: Post Graduation | E37: Marriage | F37: Others
B38: Goal Age
B39: Current Value
B40: Priority (H/M/L)
B42: Other Goals
B43: Goal | C43: Yes/No | D43: Timeframe | E43: Amount | F43: Priority (H/M/L)
B44: International Vacation
B45: Car Purchase
...

Sheet Salary Breakdown
B3: Salary Breakdown
B4: Particulars | C4: Self | E4: Spouse
B5: Basic Salary (per annum) | C5: =943600 -> 943600
B6: Employee's Contribution towards Provident Fund | C6: =4050*12 -> 48600
B7: Employer's Contribution towards Provident Fund | C7: 48600
B8: Have you opted for Voluntary Provident Fund | C8: No | E8: Yes / No
B9: Amount of VPF / annum | C9: 0
B10: Does your employer provide the option of opting for NPS | C10: Yes / No | E10: Yes / No
B11: Variable Pay (per annum) | C11: 0
B12: CTC (including variable pay) | C12: 1000000

Sheet Investments
B1: Current Mutual Funds It's easier to download a consolidated PDF from CAMS Website, use below link - detailed, non-zero balance folios, appropriate range of dates, email, PAN, enter password - once you receive the CAS on email - forward it to us with password
B3: https://www.camsonline.com/Investors/Statements/Consolidated-Account-Statement
B4: Sr. No. | C4: Fund Name | D4: Investment Date | E4: Investment Value | F4: Units | G4: Current Value | H4: Folio No | I4: Investor Name | J4: SIP Amount
B5: 1
B6: 2
B7: 3
B8: 4
B9: 5
B10: 6
B11: 7
B12: 8
C13: Total | E13: =SUM(E5:E12) -> 0 | F13: =SUM(F5:F12) -> 0 | K13: =SUM(K5:K12) -> 0
B15: Current Equity Portfolio
B16: Sr. No. | C16: Script Name | D16: No of Shares | E16: Investment Value | F16: Current Value | G16: Investor Name
B17: 1
B18: 2
B19: 3
B20: 4
B21: 5
B22: 6
B23: 7
B24: 8
B25: 9
B26: 10
B27: 11
B28: 12
... B31: 15
E32: =SUM(E17:E31) -> 0 | F32: =SUM(F17:F31) -> 0
B35: Current Debt Instruments
B36: Sr. No. | C36: Instrument | D36: Company | E36: Investment Date | F36: Investment Value | G36: Interest | H36: Current Value | I36: Maturity Date | J36: Maturity Value | K36: Investor Name
B37: 1
B38: 2
B39: 3
B40: 4
B41: 5
B42: 6
B43: 7
B44: 8
B45: 9
B46: 10
...

Sheet Insurance
B1: Current Life Insurance Policies
B2: Sr. No. | C2: Policy Name | D2: Type | E2: Premium (pa) | F2: PPT | G2: Start Date | H2: Maturity Date | I2: Life Cover | J2: Surrender Value | K2: Maturity Value | L2: Riders | M2: Nominee
B3: =Data!C6 -> Partha Lalit
B4: 1
B5: 2
B6: 3
B7: 4
C8: Total | E8: =SUM(E4:E7) -> 0 | I8: =SUM(I4:I7) -> 0 | J8: =SUM(J4:J7) -> 0 | K8: =SUM(K4:K7) -> 0
B9: =Data!E6 -> NA
B10: 1
B11: 2
E12: =SUM(E10:E11) -> 0 | I12: =SUM(I10:I11) -> 0 | J12: =SUM(J10:J11) -> 0 | K12: =SUM(K10:K11) -> 0
B13: =Data!C21 -> 0
B14: 1
B15: 2
E16: =SUM(E14:E15) -> 0 | I16: =SUM(I14:I15) -> 0 | J16: =SUM(J14:J15) -> 0 | K16: =SUM(K14:K15) -> 0
B17: =Data!D21 -> 0
B18: 1
B19: 2
E20: =SUM(E18:E19) -> 0 | I20: =SUM(I18:I19) -> 0 | J20: =SUM(J18:J19) -> 0 | K20: =SUM(K18:K19) -> 0
B23: Current General Insurance Policies
B24: Sr. No. | C24: Type | D24: Policy Name | E24: Sum Insured | F24: Annual Premium | G24: Insured | H24: Renewal Date
B25: 1 | C25: Health Insurance
B26: =B25+1 -> 2 | C26: Critical Illness
B27: =B26+1 -> 3 | C27: Personal Accident
B28: 5 | C28: Group Mediclaim
B29: 6 | C29: Group Personal Accident
C30: Total Premium | F30: =SUM(F25:F29) -> 0

Sheet Credit Cards
B3: Credit Cards
B4: Name of the card
B5: HDFC BizFirst
B6: ICICI MMT

Sheet net worth
B3: Assets
B4: Particulars | D4: =Data!D104 -> Partha Lalit | E4: =Data!E104 -> NA | F4: Joint/Others | G4: Amount | H4: % Allocation
B5: Residential Property | D5: =Data!D105 -> 0 | E5: =Data!E105 -> 0 | F5: =Data!F105 -> 0 | G5: =D5+E5+F5 -> 0 | H5: =G5/$G$43 -> #REF!
B6: Vehicle | D6: =Data!D106 -> 1 | E6: =Data!E106 -> 0 | F6: =Data!F106 -> 0 | G6: =D6+E6+F6 -> 1 | H6: =G6/$G$43 -> #REF!
B7: Jewellery (excluding gold coins) | D7: =Data!D107 -> 0 | E7: =Data!E107 -> 0 | F7: =Data!F107 -> 0 | G7: =D7+E7+F7 -> 0 | H7: =G7/$G$43 -> #REF!
B8: Inheritance of Wealth Expected | D8: =Data!D108 -> 0 | E8: =Data!E108 -> 0 | F8: =Data!F108 -> 0 | G8: =D8+E8+F8 -> 0 | H8: =G8/$G$43 -> #REF!
B9: Others | D9: =Data!D109 -> 0 | E9: =Data!E109 -> 0 | F9: =Data!F109 -> 0 | G9: =D9+E9+F9 -> 0 | H9: =G9/$G$43 -> #REF!
B10: Personal Assets | D10: =SUM(D5:D9) -> 1 | E10: =SUM(E5:E9) -> 0 | F10: =SUM(F5:F9) -> 0 | G10: =D10+E10+F10 -> 1 | H10: =G10/$G$43 -> #REF!
B11: Savings Bank/Cash in Hand | D11: =Data!D111 -> 0 | E11: =Data!E111 -> 0 | F11: =Data!F111 -> 0 | G11: =D11+E11+F11 -> 0 | H11: =G11/$G$43 -> #REF!
B12: Fixed Deposits | D12: =Data!D112 -> 35000 | E12: =Data!E112 -> 0 | F12: =Data!F112 -> 0 | G12: =D12+E12+F12 -> 35000 | H12: =G12/$G$43 -> #REF!
B13: Recurring Deposits | D13: =Data!D113 -> 0 | E13: =Data!E113 -> 0 | F13: =Data!F113 -> 0 | G13: =D13+E13+F13 -> 0 | H13: =G13/$G$43 -> #REF!
B14: Total Liquid Assets | D14: =SUM(D11:D13) -> 35000 | E14: =SUM(E11:E13) -> 0 | F14: =SUM(F11:F13) -> 0 | G14: =D14+E14+F14 -> 35000 | H14: =G14/$G$43 -> #REF!
B15: Receivables from Friends & Family | D15: =Data!D115 -> 0 | E15: =Data!E115 -> 0 | F15: =Data!F115 -> 0 | G15: =D15+E15+F15 -> 0 | H15: =G15/$G$43 -> #REF!
B16: PPF (Public Provident Fund) | D16: =Data!D116 -> 0 | E16: =Data!E116 -> 0 | F16: =Data!F116 -> 0 | G16: =D16+E16+F16 -> 0 | H16: =G16/$G$43 -> #REF!
B17: Sukanya Samridhi Yojna | D17: =Data!D117 -> 0 | E17: =Data!E117 -> 0 | F17: =Data!F117 -> 0 | G17: =D17+E17+F17 -> 0 | H17: =G17/$G$43 -> #REF!
B18: National Pension Scheme (Tier I) Active Choice or Auto Choice & Asset Allocation | D18: =Data!D118 -> 0 | E18: =Data!E118 -> 0 | F18: =Data!F118 -> 0 | G18: =D18+E18+F18 -> 0 | H18: =G18/$G$43 -> #REF!
B19: National Pension Scheme (Tier II) Active Choice or Auto Choice & Asset Allocation | D19: =Data!D119 -> 0 | E19: =Data!E119 -> 0 | F19: =Data!F119 -> 0 | G19: =D19+E19+F19 -> 0 | H19: =G19/$G$43 -> #REF!
B20: Employees' Provident Fund (EPF) | D20: =Data!D120 -> 0 | E20: =Data!E120 -> 0 | F20: =Data!F120 -> 0 | G20: =D20+E20+F20 -> 0 | H20: =G20/$G$43 -> #REF!
B21: RBI Fixed / Floating Rate Bonds | D21: =Data!D121 -> 0 | E21: =Data!E121 -> 0 | F21: =Data!F121 -> 0 | G21: =D21+E21+F21 -> 0 | H21: =G21/$G$43 -> #REF!
B22: Market Linked Debentures | D22: =Data!D122 -> 0 | E22: =Data!E122 -> 0 | F22: =Data!F122 -> 0 | G22: =D22+E22+F22 -> 0 | H22: =G22/$G$43 -> #REF!
B23: National Savings Certificate | D23: =Data!D123 -> 0 | E23: =Data!E123 -> 0 | F23: =Data!F123 -> 0 | G23: =D23+E23+F23 -> 0 | H23: =G23/$G$43 -> #REF!
B24: Post Office Monthly Income Scheme | D24: =Data!D124 -> 0 | E24: =Data!E124 -> 0 | F24: =Data!F124 -> 0 | G24: =D24+E24+F24 -> 0 | H24: =G24/$G$43 -> #REF!
B25: Kisan Vikas Patra | D25: =Data!D125 -> 0 | E25: =Data!E125 -> 0 | F25: =Data!F125 -> 0 | G25: =D25+E25+F25 -> 0 | H25: =G25/$G$43 -> #REF!
B26: Senior Citizen Savings Scheme | D26: =Data!D126 -> 0 | E26: =Data!E126 -> 0 | F26: =Data!F126 -> 0 | G26: =D26+E26+F26 -> 0 | H26: =G26/$G$43 -> #REF!
... B29: Bonds/Debentures/CDs | D29: =Data!D129 -> 0 | E29: =Data!E129 -> 0 | F29: =Data!F129 -> 0 | G29: =D29+E29+F29 -> 0 | H29: =G29/$G$43 -> #REF!
B30: Total Debt Assets | D30: =SUM(D15:D29) -> 0 | E30: =SUM(E15:E29) -> 0 | F30: =SUM(F15:F29) -> 0 | G30: =D30+E30+F30 -> 0 | H30: =G30/$G$43 -> #REF!
B31: Stocks - (India) - DIY | D31: =Data!D132 -> 0 | E31: =Data!E132 -> 0 | F31: =Data!F132 -> 0 | G31: =D31+E31+F31 -> 0 | H31: =G31/$G$43 -> #REF!
B32: Stocks - (Global) - DIY | D32: =Data!D133 -> 0 | E32: =Data!E133 -> 0 | F32: =Data!F133 -> 0 | G32: =D32+E32+F32 -> 0 | H32: =G32/$G$43 -> #REF!
B33: Equity Mutual Funds | D33: =Data!D135 -> 133000 | E33: =Data!E135 -> 0 | F33: =Data!F135 -> 0 | G33: =D33+E33+F33 -> 133000 | H33: =G33/$G$43 -> #REF!
B34: Direct Stocks - Smallcase | D34: =Data!D137 -> 0 | E34: =Data!E137 -> 0 | F34: =Data!F137 -> 0 | G34: =D34+E34+F34 -> 0 | H34: =G34/$G$43 -> #REF!
B35: Portfolio Management Services - Direct Stocks | D35: =Data!D138 -> 6500 | E35: =Data!E138 -> 0 | F35: =Data!F138 -> 0 | G35: =D35+E35+F35 -> 6500 | H35: =G35/$G$43 -> #REF!
B36: Equity Mutual Funds | D36: =Data!#REF! -> #REF! | E36: =Data!#REF! -> #REF! | F36: =Data!#REF! -> #REF! | G36: =D36+E36+F36 -> #REF! | H36: =G36/$G$43 -> #REF!
B37: Unit-linked Insurance Policies (Surrender Value) | D37: =Data!D139 -> 0 | E37: =Data!E139 -> 0 | F37: =Data!F139 -> 0 | G37: =D37+E37+F37 -> 0 | H37: =G37/$G$43 -> #REF!
B38: Total Equity Assets | D38: =SUM(D31:D37) -> #REF! | E38: =SUM(E31:E37) -> #REF! | F38: =SUM(F31:F37) -> #REF! | G38: =D38+E38+F38 -> #REF! | H38: =G38/$G$43 -> #REF!
B39: Gold / Silver (ETFs/Bars/Coins/Digital) | D39: =Data!D141 -> 0 | E39: =Data!E141 -> 0 | F39: =Data!F141 -> 0 | G39: =D39+E39+F39 -> 0 | H39: =G39/$G$43 -> #REF!
B40: Sovereign Gold Bonds | D40: =Data!D142 -> 0 | E40: =Data!E142 -> 0 | F40: =Data!F142 -> 0 | G40: =D40+E40+F40 -> 0 | H40: =G40/$G$43 -> #REF!
B41: Real Estate Investments | D41: =Data!D143 -> 0 | E41: =Data!E143 -> 0 | F41: =Data!F143 -> 0 | G41: =D41+E41+F41 -> 0 | H41: =G41/$G$43 -> #REF!
B42: Crypto Currency (Speculative) | D42: =Data!D144 -> 0 | E42: =Data!E144 -> 0 | F42: =Data!F144 -> 0 | G42: =D42+E42+F42 -> 0 | H42: =G42/$G$43 -> #REF!
B43: Total Investment Assets | D43: =SUM(D38:D42,D30,D14) -> #REF! | E43: =SUM(E38:E42,E30,E14) -> #REF! | F43: =SUM(F38:F42,F30,F14) -> #REF! | G43: =SUM(G38:G42,G30,G14) -> #REF! | H43: =SUM(H38:H42,H30,H14) -> #REF!
B47: Liabilities
...
